{
 "cells": [
  {
   "cell_type": "markdown",
   "id": "3a4eea52",
   "metadata": {},
   "source": [
    "## Keras Tuner-Decide Number of Hidden Layers And Neuron in Neural Network"
   ]
  },
  {
   "cell_type": "code",
   "execution_count": 3,
   "id": "fab14ade",
   "metadata": {},
   "outputs": [
    {
     "name": "stdout",
     "output_type": "stream",
     "text": [
      "Requirement already satisfied: tensorflow in ./anaconda3/lib/python3.11/site-packages (2.14.0)\n",
      "Requirement already satisfied: tensorflow-macos==2.14.0 in ./anaconda3/lib/python3.11/site-packages (from tensorflow) (2.14.0)\n",
      "Requirement already satisfied: absl-py>=1.0.0 in ./anaconda3/lib/python3.11/site-packages (from tensorflow-macos==2.14.0->tensorflow) (2.0.0)\n",
      "Requirement already satisfied: astunparse>=1.6.0 in ./anaconda3/lib/python3.11/site-packages (from tensorflow-macos==2.14.0->tensorflow) (1.6.3)\n",
      "Requirement already satisfied: flatbuffers>=23.5.26 in ./anaconda3/lib/python3.11/site-packages (from tensorflow-macos==2.14.0->tensorflow) (23.5.26)\n",
      "Requirement already satisfied: gast!=0.5.0,!=0.5.1,!=0.5.2,>=0.2.1 in ./anaconda3/lib/python3.11/site-packages (from tensorflow-macos==2.14.0->tensorflow) (0.5.4)\n",
      "Requirement already satisfied: google-pasta>=0.1.1 in ./anaconda3/lib/python3.11/site-packages (from tensorflow-macos==2.14.0->tensorflow) (0.2.0)\n",
      "Requirement already satisfied: h5py>=2.9.0 in ./anaconda3/lib/python3.11/site-packages (from tensorflow-macos==2.14.0->tensorflow) (3.7.0)\n",
      "Requirement already satisfied: libclang>=13.0.0 in ./anaconda3/lib/python3.11/site-packages (from tensorflow-macos==2.14.0->tensorflow) (16.0.6)\n",
      "Requirement already satisfied: ml-dtypes==0.2.0 in ./anaconda3/lib/python3.11/site-packages (from tensorflow-macos==2.14.0->tensorflow) (0.2.0)\n",
      "Requirement already satisfied: numpy>=1.23.5 in ./anaconda3/lib/python3.11/site-packages (from tensorflow-macos==2.14.0->tensorflow) (1.25.2)\n",
      "Requirement already satisfied: opt-einsum>=2.3.2 in ./anaconda3/lib/python3.11/site-packages (from tensorflow-macos==2.14.0->tensorflow) (3.3.0)\n",
      "Requirement already satisfied: packaging in ./anaconda3/lib/python3.11/site-packages (from tensorflow-macos==2.14.0->tensorflow) (23.0)\n",
      "Requirement already satisfied: protobuf!=4.21.0,!=4.21.1,!=4.21.2,!=4.21.3,!=4.21.4,!=4.21.5,<5.0.0dev,>=3.20.3 in ./anaconda3/lib/python3.11/site-packages (from tensorflow-macos==2.14.0->tensorflow) (4.24.3)\n",
      "Requirement already satisfied: setuptools in ./anaconda3/lib/python3.11/site-packages (from tensorflow-macos==2.14.0->tensorflow) (67.8.0)\n",
      "Requirement already satisfied: six>=1.12.0 in ./anaconda3/lib/python3.11/site-packages (from tensorflow-macos==2.14.0->tensorflow) (1.16.0)\n",
      "Requirement already satisfied: termcolor>=1.1.0 in ./anaconda3/lib/python3.11/site-packages (from tensorflow-macos==2.14.0->tensorflow) (2.3.0)\n",
      "Requirement already satisfied: typing-extensions>=3.6.6 in ./anaconda3/lib/python3.11/site-packages (from tensorflow-macos==2.14.0->tensorflow) (4.6.3)\n",
      "Requirement already satisfied: wrapt<1.15,>=1.11.0 in ./anaconda3/lib/python3.11/site-packages (from tensorflow-macos==2.14.0->tensorflow) (1.14.1)\n",
      "Requirement already satisfied: tensorflow-io-gcs-filesystem>=0.23.1 in ./anaconda3/lib/python3.11/site-packages (from tensorflow-macos==2.14.0->tensorflow) (0.34.0)\n",
      "Requirement already satisfied: grpcio<2.0,>=1.24.3 in ./anaconda3/lib/python3.11/site-packages (from tensorflow-macos==2.14.0->tensorflow) (1.59.0)\n",
      "Requirement already satisfied: tensorboard<2.15,>=2.14 in ./anaconda3/lib/python3.11/site-packages (from tensorflow-macos==2.14.0->tensorflow) (2.14.1)\n",
      "Requirement already satisfied: tensorflow-estimator<2.15,>=2.14.0 in ./anaconda3/lib/python3.11/site-packages (from tensorflow-macos==2.14.0->tensorflow) (2.14.0)\n",
      "Requirement already satisfied: keras<2.15,>=2.14.0 in ./anaconda3/lib/python3.11/site-packages (from tensorflow-macos==2.14.0->tensorflow) (2.14.0)\n",
      "Requirement already satisfied: wheel<1.0,>=0.23.0 in ./anaconda3/lib/python3.11/site-packages (from astunparse>=1.6.0->tensorflow-macos==2.14.0->tensorflow) (0.38.4)\n",
      "Requirement already satisfied: google-auth<3,>=1.6.3 in ./anaconda3/lib/python3.11/site-packages (from tensorboard<2.15,>=2.14->tensorflow-macos==2.14.0->tensorflow) (2.23.2)\n",
      "Requirement already satisfied: google-auth-oauthlib<1.1,>=0.5 in ./anaconda3/lib/python3.11/site-packages (from tensorboard<2.15,>=2.14->tensorflow-macos==2.14.0->tensorflow) (1.0.0)\n",
      "Requirement already satisfied: markdown>=2.6.8 in ./anaconda3/lib/python3.11/site-packages (from tensorboard<2.15,>=2.14->tensorflow-macos==2.14.0->tensorflow) (3.4.1)\n",
      "Requirement already satisfied: requests<3,>=2.21.0 in ./anaconda3/lib/python3.11/site-packages (from tensorboard<2.15,>=2.14->tensorflow-macos==2.14.0->tensorflow) (2.29.0)\n",
      "Requirement already satisfied: tensorboard-data-server<0.8.0,>=0.7.0 in ./anaconda3/lib/python3.11/site-packages (from tensorboard<2.15,>=2.14->tensorflow-macos==2.14.0->tensorflow) (0.7.1)\n",
      "Requirement already satisfied: werkzeug>=1.0.1 in ./anaconda3/lib/python3.11/site-packages (from tensorboard<2.15,>=2.14->tensorflow-macos==2.14.0->tensorflow) (2.2.3)\n",
      "Requirement already satisfied: cachetools<6.0,>=2.0.0 in ./anaconda3/lib/python3.11/site-packages (from google-auth<3,>=1.6.3->tensorboard<2.15,>=2.14->tensorflow-macos==2.14.0->tensorflow) (5.3.1)\n",
      "Requirement already satisfied: pyasn1-modules>=0.2.1 in ./anaconda3/lib/python3.11/site-packages (from google-auth<3,>=1.6.3->tensorboard<2.15,>=2.14->tensorflow-macos==2.14.0->tensorflow) (0.2.8)\n",
      "Requirement already satisfied: rsa<5,>=3.1.4 in ./anaconda3/lib/python3.11/site-packages (from google-auth<3,>=1.6.3->tensorboard<2.15,>=2.14->tensorflow-macos==2.14.0->tensorflow) (4.9)\n",
      "Requirement already satisfied: requests-oauthlib>=0.7.0 in ./anaconda3/lib/python3.11/site-packages (from google-auth-oauthlib<1.1,>=0.5->tensorboard<2.15,>=2.14->tensorflow-macos==2.14.0->tensorflow) (1.3.1)\n",
      "Requirement already satisfied: charset-normalizer<4,>=2 in ./anaconda3/lib/python3.11/site-packages (from requests<3,>=2.21.0->tensorboard<2.15,>=2.14->tensorflow-macos==2.14.0->tensorflow) (2.0.4)\n",
      "Requirement already satisfied: idna<4,>=2.5 in ./anaconda3/lib/python3.11/site-packages (from requests<3,>=2.21.0->tensorboard<2.15,>=2.14->tensorflow-macos==2.14.0->tensorflow) (3.4)\n",
      "Requirement already satisfied: urllib3<1.27,>=1.21.1 in ./anaconda3/lib/python3.11/site-packages (from requests<3,>=2.21.0->tensorboard<2.15,>=2.14->tensorflow-macos==2.14.0->tensorflow) (1.26.16)\n",
      "Requirement already satisfied: certifi>=2017.4.17 in ./anaconda3/lib/python3.11/site-packages (from requests<3,>=2.21.0->tensorboard<2.15,>=2.14->tensorflow-macos==2.14.0->tensorflow) (2023.5.7)\n",
      "Requirement already satisfied: MarkupSafe>=2.1.1 in ./anaconda3/lib/python3.11/site-packages (from werkzeug>=1.0.1->tensorboard<2.15,>=2.14->tensorflow-macos==2.14.0->tensorflow) (2.1.1)\n",
      "Requirement already satisfied: pyasn1<0.5.0,>=0.4.6 in ./anaconda3/lib/python3.11/site-packages (from pyasn1-modules>=0.2.1->google-auth<3,>=1.6.3->tensorboard<2.15,>=2.14->tensorflow-macos==2.14.0->tensorflow) (0.4.8)\n",
      "Requirement already satisfied: oauthlib>=3.0.0 in ./anaconda3/lib/python3.11/site-packages (from requests-oauthlib>=0.7.0->google-auth-oauthlib<1.1,>=0.5->tensorboard<2.15,>=2.14->tensorflow-macos==2.14.0->tensorflow) (3.2.2)\n",
      "Note: you may need to restart the kernel to use updated packages.\n"
     ]
    }
   ],
   "source": [
    "pip install --upgrade tensorflow"
   ]
  },
  {
   "cell_type": "code",
   "execution_count": 8,
   "id": "980bc95b",
   "metadata": {},
   "outputs": [],
   "source": [
    "import pandas as pd\n",
    "from tensorflow import keras\n",
    "from tensorflow.keras import layers\n",
    "from kerastuner.tuners import RandomSearch"
   ]
  },
  {
   "cell_type": "code",
   "execution_count": 9,
   "id": "5eb1cdec",
   "metadata": {},
   "outputs": [],
   "source": [
    "# air qulaity index prob (linear regression)\n",
    "df=pd.read_csv('Real_Combine.csv')"
   ]
  },
  {
   "cell_type": "code",
   "execution_count": 10,
   "id": "322254ea",
   "metadata": {},
   "outputs": [
    {
     "data": {
      "text/html": [
       "<div>\n",
       "<style scoped>\n",
       "    .dataframe tbody tr th:only-of-type {\n",
       "        vertical-align: middle;\n",
       "    }\n",
       "\n",
       "    .dataframe tbody tr th {\n",
       "        vertical-align: top;\n",
       "    }\n",
       "\n",
       "    .dataframe thead th {\n",
       "        text-align: right;\n",
       "    }\n",
       "</style>\n",
       "<table border=\"1\" class=\"dataframe\">\n",
       "  <thead>\n",
       "    <tr style=\"text-align: right;\">\n",
       "      <th></th>\n",
       "      <th>T</th>\n",
       "      <th>TM</th>\n",
       "      <th>Tm</th>\n",
       "      <th>SLP</th>\n",
       "      <th>H</th>\n",
       "      <th>VV</th>\n",
       "      <th>V</th>\n",
       "      <th>VM</th>\n",
       "      <th>PM 2.5</th>\n",
       "    </tr>\n",
       "  </thead>\n",
       "  <tbody>\n",
       "    <tr>\n",
       "      <th>0</th>\n",
       "      <td>7.4</td>\n",
       "      <td>9.8</td>\n",
       "      <td>4.8</td>\n",
       "      <td>1017.6</td>\n",
       "      <td>93.0</td>\n",
       "      <td>0.5</td>\n",
       "      <td>4.3</td>\n",
       "      <td>9.4</td>\n",
       "      <td>219.720833</td>\n",
       "    </tr>\n",
       "    <tr>\n",
       "      <th>1</th>\n",
       "      <td>7.8</td>\n",
       "      <td>12.7</td>\n",
       "      <td>4.4</td>\n",
       "      <td>1018.5</td>\n",
       "      <td>87.0</td>\n",
       "      <td>0.6</td>\n",
       "      <td>4.4</td>\n",
       "      <td>11.1</td>\n",
       "      <td>182.187500</td>\n",
       "    </tr>\n",
       "    <tr>\n",
       "      <th>2</th>\n",
       "      <td>6.7</td>\n",
       "      <td>13.4</td>\n",
       "      <td>2.4</td>\n",
       "      <td>1019.4</td>\n",
       "      <td>82.0</td>\n",
       "      <td>0.6</td>\n",
       "      <td>4.8</td>\n",
       "      <td>11.1</td>\n",
       "      <td>154.037500</td>\n",
       "    </tr>\n",
       "    <tr>\n",
       "      <th>3</th>\n",
       "      <td>8.6</td>\n",
       "      <td>15.5</td>\n",
       "      <td>3.3</td>\n",
       "      <td>1018.7</td>\n",
       "      <td>72.0</td>\n",
       "      <td>0.8</td>\n",
       "      <td>8.1</td>\n",
       "      <td>20.6</td>\n",
       "      <td>223.208333</td>\n",
       "    </tr>\n",
       "    <tr>\n",
       "      <th>4</th>\n",
       "      <td>12.4</td>\n",
       "      <td>20.9</td>\n",
       "      <td>4.4</td>\n",
       "      <td>1017.3</td>\n",
       "      <td>61.0</td>\n",
       "      <td>1.3</td>\n",
       "      <td>8.7</td>\n",
       "      <td>22.2</td>\n",
       "      <td>200.645833</td>\n",
       "    </tr>\n",
       "  </tbody>\n",
       "</table>\n",
       "</div>"
      ],
      "text/plain": [
       "      T    TM   Tm     SLP     H   VV    V    VM      PM 2.5\n",
       "0   7.4   9.8  4.8  1017.6  93.0  0.5  4.3   9.4  219.720833\n",
       "1   7.8  12.7  4.4  1018.5  87.0  0.6  4.4  11.1  182.187500\n",
       "2   6.7  13.4  2.4  1019.4  82.0  0.6  4.8  11.1  154.037500\n",
       "3   8.6  15.5  3.3  1018.7  72.0  0.8  8.1  20.6  223.208333\n",
       "4  12.4  20.9  4.4  1017.3  61.0  1.3  8.7  22.2  200.645833"
      ]
     },
     "execution_count": 10,
     "metadata": {},
     "output_type": "execute_result"
    }
   ],
   "source": [
    "df.head()"
   ]
  },
  {
   "cell_type": "code",
   "execution_count": 11,
   "id": "dc33ff6a",
   "metadata": {},
   "outputs": [],
   "source": [
    "X = df.iloc[:,:-1] ## independent features\n",
    "Y = df.iloc[:,-1] ## dependent features"
   ]
  },
  {
   "cell_type": "markdown",
   "id": "75ceaf12",
   "metadata": {},
   "source": [
    "### Hyperparameters\n",
    "1. How many number of hidden layers we should have?\n",
    "2. How many number of neurons we should have in hidden layers?\n",
    "3. Learning rate"
   ]
  },
  {
   "cell_type": "code",
   "execution_count": 29,
   "id": "78990047",
   "metadata": {},
   "outputs": [],
   "source": [
    "# The no of hidden layers are between 2 to 20.\n",
    "# The no of nuerons are btw 32 to 512.\n",
    "# We have 1 output layer , using adam optimiser and we have use hp.choice \n",
    "# so we can choose btw these three learning values.\n",
    "# we have use mean_absolute error as loss function and mean_absolute_error as metrics\n",
    "def build_model(hp):\n",
    "    model = keras.Sequential()\n",
    "    for i in range(hp.Int('num_layers',2,20)):\n",
    "        model.add(layers.Dense(units=hp.Int('units_'+str(i),\n",
    "                                           min_value=32,\n",
    "                                           max_value=512,\n",
    "                                           step=32),\n",
    "                              activation='relu'))\n",
    "        model.add(layers.Dense(1,activation='linear'))\n",
    "        model.compile(\n",
    "        optimizer=keras.optimizers.Adam(\n",
    "        hp.Choice('learning_rate',[1e-2,1e-3,1e-4])),\n",
    "        loss='mean_absoulte_error',\n",
    "        metrics=['mean_absolute_error'])\n",
    "        return model"
   ]
  },
  {
   "cell_type": "code",
   "execution_count": 30,
   "id": "1c0b5f58",
   "metadata": {},
   "outputs": [
    {
     "name": "stderr",
     "output_type": "stream",
     "text": [
      "WARNING:absl:At this time, the v2.11+ optimizer `tf.keras.optimizers.Adam` runs slowly on M1/M2 Macs, please use the legacy Keras optimizer instead, located at `tf.keras.optimizers.legacy.Adam`.\n"
     ]
    }
   ],
   "source": [
    "tuner = RandomSearch(\n",
    "    hypermodel=build_model,\n",
    "    objective=\"val_mean_absolute_error\",\n",
    "    max_trials=5,\n",
    "    executions_per_trial=3,\n",
    "    directory='project',\n",
    "    project_name='Air Quality Index',\n",
    ")"
   ]
  },
  {
   "cell_type": "code",
   "execution_count": 31,
   "id": "3de54e1c",
   "metadata": {},
   "outputs": [
    {
     "name": "stdout",
     "output_type": "stream",
     "text": [
      "Search space summary\n",
      "Default search space size: 3\n",
      "num_layers (Int)\n",
      "{'default': None, 'conditions': [], 'min_value': 2, 'max_value': 20, 'step': 1, 'sampling': 'linear'}\n",
      "units_0 (Int)\n",
      "{'default': None, 'conditions': [], 'min_value': 32, 'max_value': 512, 'step': 32, 'sampling': 'linear'}\n",
      "learning_rate (Choice)\n",
      "{'default': 0.01, 'conditions': [], 'values': [0.01, 0.001, 0.0001], 'ordered': True}\n"
     ]
    }
   ],
   "source": [
    "tuner.search_space_summary()"
   ]
  },
  {
   "cell_type": "code",
   "execution_count": 33,
   "id": "ebbcd047",
   "metadata": {},
   "outputs": [],
   "source": [
    "from sklearn.model_selection import train_test_split\n",
    "X_train, X_test, Y_train, Y_test = train_test_split(X, Y, test_size=0.3, random_state=0)\n"
   ]
  },
  {
   "cell_type": "code",
   "execution_count": 36,
   "id": "185d3562",
   "metadata": {},
   "outputs": [
    {
     "name": "stdout",
     "output_type": "stream",
     "text": [
      "Trial 2 Complete [00h 00m 00s]\n",
      "\n",
      "Best val_mean_absolute_error So Far: None\n",
      "Total elapsed time: 00h 00m 00s\n",
      "\n",
      "Search: Running Trial #3\n",
      "\n",
      "Value             |Best Value So Far |Hyperparameter\n",
      "14                |3                 |num_layers\n",
      "32                |192               |units_0\n",
      "0.001             |0.001             |learning_rate\n",
      "\n"
     ]
    },
    {
     "name": "stderr",
     "output_type": "stream",
     "text": [
      "WARNING:absl:At this time, the v2.11+ optimizer `tf.keras.optimizers.Adam` runs slowly on M1/M2 Macs, please use the legacy Keras optimizer instead, located at `tf.keras.optimizers.legacy.Adam`.\n"
     ]
    },
    {
     "name": "stdout",
     "output_type": "stream",
     "text": [
      "Epoch 1/5\n"
     ]
    },
    {
     "name": "stderr",
     "output_type": "stream",
     "text": [
      "Traceback (most recent call last):\n",
      "  File \"/Users/khatriaryan/anaconda3/lib/python3.11/site-packages/keras_tuner/src/engine/base_tuner.py\", line 270, in _try_run_and_update_trial\n",
      "    self._run_and_update_trial(trial, *fit_args, **fit_kwargs)\n",
      "  File \"/Users/khatriaryan/anaconda3/lib/python3.11/site-packages/keras_tuner/src/engine/base_tuner.py\", line 235, in _run_and_update_trial\n",
      "    results = self.run_trial(trial, *fit_args, **fit_kwargs)\n",
      "              ^^^^^^^^^^^^^^^^^^^^^^^^^^^^^^^^^^^^^^^^^^^^^^\n",
      "  File \"/Users/khatriaryan/anaconda3/lib/python3.11/site-packages/keras_tuner/src/engine/tuner.py\", line 314, in run_trial\n",
      "    obj_value = self._build_and_fit_model(trial, *args, **copied_kwargs)\n",
      "                ^^^^^^^^^^^^^^^^^^^^^^^^^^^^^^^^^^^^^^^^^^^^^^^^^^^^^^^^\n",
      "  File \"/Users/khatriaryan/anaconda3/lib/python3.11/site-packages/keras_tuner/src/engine/tuner.py\", line 233, in _build_and_fit_model\n",
      "    results = self.hypermodel.fit(hp, model, *args, **kwargs)\n",
      "              ^^^^^^^^^^^^^^^^^^^^^^^^^^^^^^^^^^^^^^^^^^^^^^^\n",
      "  File \"/Users/khatriaryan/anaconda3/lib/python3.11/site-packages/keras_tuner/src/engine/hypermodel.py\", line 144, in fit\n",
      "    return model.fit(*args, **kwargs)\n",
      "           ^^^^^^^^^^^^^^^^^^^^^^^^^^\n",
      "  File \"/Users/khatriaryan/anaconda3/lib/python3.11/site-packages/keras/src/utils/traceback_utils.py\", line 70, in error_handler\n",
      "    raise e.with_traceback(filtered_tb) from None\n",
      "  File \"/var/folders/9c/2115fdss5hn7vy9wx2ldrjq40000gn/T/__autograph_generated_file2u8audgp.py\", line 18, in tf__train_function\n",
      "    raise\n",
      "ValueError: in user code:\n",
      "\n",
      "    File \"/Users/khatriaryan/anaconda3/lib/python3.11/site-packages/keras/src/engine/training.py\", line 1377, in train_function  *\n",
      "        return step_function(self, iterator)\n",
      "    File \"/Users/khatriaryan/anaconda3/lib/python3.11/site-packages/keras/src/engine/training.py\", line 1360, in step_function  **\n",
      "        outputs = model.distribute_strategy.run(run_step, args=(data,))\n",
      "    File \"/Users/khatriaryan/anaconda3/lib/python3.11/site-packages/keras/src/engine/training.py\", line 1349, in run_step  **\n",
      "        outputs = model.train_step(data)\n",
      "    File \"/Users/khatriaryan/anaconda3/lib/python3.11/site-packages/keras/src/engine/training.py\", line 1127, in train_step\n",
      "        loss = self.compute_loss(x, y, y_pred, sample_weight)\n",
      "    File \"/Users/khatriaryan/anaconda3/lib/python3.11/site-packages/keras/src/engine/training.py\", line 1185, in compute_loss\n",
      "        return self.compiled_loss(\n",
      "    File \"/Users/khatriaryan/anaconda3/lib/python3.11/site-packages/keras/src/engine/compile_utils.py\", line 252, in __call__\n",
      "        self.build(y_pred)\n",
      "    File \"/Users/khatriaryan/anaconda3/lib/python3.11/site-packages/keras/src/engine/compile_utils.py\", line 194, in build\n",
      "        self._losses = tf.nest.map_structure(\n",
      "    File \"/Users/khatriaryan/anaconda3/lib/python3.11/site-packages/keras/src/engine/compile_utils.py\", line 365, in _get_loss_object\n",
      "        loss = losses_mod.get(loss)\n",
      "    File \"/Users/khatriaryan/anaconda3/lib/python3.11/site-packages/keras/src/losses.py\", line 2965, in get\n",
      "        return deserialize(identifier, use_legacy_format=use_legacy_format)\n",
      "    File \"/Users/khatriaryan/anaconda3/lib/python3.11/site-packages/keras/src/losses.py\", line 2912, in deserialize\n",
      "        return legacy_serialization.deserialize_keras_object(\n",
      "    File \"/Users/khatriaryan/anaconda3/lib/python3.11/site-packages/keras/src/saving/legacy/serialization.py\", line 537, in deserialize_keras_object\n",
      "        raise ValueError(\n",
      "\n",
      "    ValueError: Unknown loss function: 'mean_absoulte_error'. Please ensure you are using a `keras.utils.custom_object_scope` and that this object is included in the scope. See https://www.tensorflow.org/guide/keras/save_and_serialize#registering_the_custom_object for details.\n",
      "\n"
     ]
    },
    {
     "ename": "RuntimeError",
     "evalue": "Number of consecutive failures exceeded the limit of 3.\nTraceback (most recent call last):\n  File \"/Users/khatriaryan/anaconda3/lib/python3.11/site-packages/keras_tuner/src/engine/base_tuner.py\", line 270, in _try_run_and_update_trial\n    self._run_and_update_trial(trial, *fit_args, **fit_kwargs)\n  File \"/Users/khatriaryan/anaconda3/lib/python3.11/site-packages/keras_tuner/src/engine/base_tuner.py\", line 235, in _run_and_update_trial\n    results = self.run_trial(trial, *fit_args, **fit_kwargs)\n              ^^^^^^^^^^^^^^^^^^^^^^^^^^^^^^^^^^^^^^^^^^^^^^\n  File \"/Users/khatriaryan/anaconda3/lib/python3.11/site-packages/keras_tuner/src/engine/tuner.py\", line 314, in run_trial\n    obj_value = self._build_and_fit_model(trial, *args, **copied_kwargs)\n                ^^^^^^^^^^^^^^^^^^^^^^^^^^^^^^^^^^^^^^^^^^^^^^^^^^^^^^^^\n  File \"/Users/khatriaryan/anaconda3/lib/python3.11/site-packages/keras_tuner/src/engine/tuner.py\", line 233, in _build_and_fit_model\n    results = self.hypermodel.fit(hp, model, *args, **kwargs)\n              ^^^^^^^^^^^^^^^^^^^^^^^^^^^^^^^^^^^^^^^^^^^^^^^\n  File \"/Users/khatriaryan/anaconda3/lib/python3.11/site-packages/keras_tuner/src/engine/hypermodel.py\", line 144, in fit\n    return model.fit(*args, **kwargs)\n           ^^^^^^^^^^^^^^^^^^^^^^^^^^\n  File \"/Users/khatriaryan/anaconda3/lib/python3.11/site-packages/keras/src/utils/traceback_utils.py\", line 70, in error_handler\n    raise e.with_traceback(filtered_tb) from None\n  File \"/var/folders/9c/2115fdss5hn7vy9wx2ldrjq40000gn/T/__autograph_generated_file2u8audgp.py\", line 18, in tf__train_function\n    raise\nValueError: in user code:\n\n    File \"/Users/khatriaryan/anaconda3/lib/python3.11/site-packages/keras/src/engine/training.py\", line 1377, in train_function  *\n        return step_function(self, iterator)\n    File \"/Users/khatriaryan/anaconda3/lib/python3.11/site-packages/keras/src/engine/training.py\", line 1360, in step_function  **\n        outputs = model.distribute_strategy.run(run_step, args=(data,))\n    File \"/Users/khatriaryan/anaconda3/lib/python3.11/site-packages/keras/src/engine/training.py\", line 1349, in run_step  **\n        outputs = model.train_step(data)\n    File \"/Users/khatriaryan/anaconda3/lib/python3.11/site-packages/keras/src/engine/training.py\", line 1127, in train_step\n        loss = self.compute_loss(x, y, y_pred, sample_weight)\n    File \"/Users/khatriaryan/anaconda3/lib/python3.11/site-packages/keras/src/engine/training.py\", line 1185, in compute_loss\n        return self.compiled_loss(\n    File \"/Users/khatriaryan/anaconda3/lib/python3.11/site-packages/keras/src/engine/compile_utils.py\", line 252, in __call__\n        self.build(y_pred)\n    File \"/Users/khatriaryan/anaconda3/lib/python3.11/site-packages/keras/src/engine/compile_utils.py\", line 194, in build\n        self._losses = tf.nest.map_structure(\n    File \"/Users/khatriaryan/anaconda3/lib/python3.11/site-packages/keras/src/engine/compile_utils.py\", line 365, in _get_loss_object\n        loss = losses_mod.get(loss)\n    File \"/Users/khatriaryan/anaconda3/lib/python3.11/site-packages/keras/src/losses.py\", line 2965, in get\n        return deserialize(identifier, use_legacy_format=use_legacy_format)\n    File \"/Users/khatriaryan/anaconda3/lib/python3.11/site-packages/keras/src/losses.py\", line 2912, in deserialize\n        return legacy_serialization.deserialize_keras_object(\n    File \"/Users/khatriaryan/anaconda3/lib/python3.11/site-packages/keras/src/saving/legacy/serialization.py\", line 537, in deserialize_keras_object\n        raise ValueError(\n\n    ValueError: Unknown loss function: 'mean_absoulte_error'. Please ensure you are using a `keras.utils.custom_object_scope` and that this object is included in the scope. See https://www.tensorflow.org/guide/keras/save_and_serialize#registering_the_custom_object for details.\n\n",
     "output_type": "error",
     "traceback": [
      "\u001b[0;31m---------------------------------------------------------------------------\u001b[0m",
      "\u001b[0;31mRuntimeError\u001b[0m                              Traceback (most recent call last)",
      "Cell \u001b[0;32mIn[36], line 1\u001b[0m\n\u001b[0;32m----> 1\u001b[0m tuner\u001b[38;5;241m.\u001b[39msearch(X_train, Y_train,\n\u001b[1;32m      2\u001b[0m              epochs\u001b[38;5;241m=\u001b[39m\u001b[38;5;241m5\u001b[39m,\n\u001b[1;32m      3\u001b[0m              validation_data\u001b[38;5;241m=\u001b[39m(X_test, Y_test))\n",
      "File \u001b[0;32m~/anaconda3/lib/python3.11/site-packages/keras_tuner/src/engine/base_tuner.py:231\u001b[0m, in \u001b[0;36mBaseTuner.search\u001b[0;34m(self, *fit_args, **fit_kwargs)\u001b[0m\n\u001b[1;32m    229\u001b[0m     \u001b[38;5;28mself\u001b[39m\u001b[38;5;241m.\u001b[39mon_trial_begin(trial)\n\u001b[1;32m    230\u001b[0m     \u001b[38;5;28mself\u001b[39m\u001b[38;5;241m.\u001b[39m_try_run_and_update_trial(trial, \u001b[38;5;241m*\u001b[39mfit_args, \u001b[38;5;241m*\u001b[39m\u001b[38;5;241m*\u001b[39mfit_kwargs)\n\u001b[0;32m--> 231\u001b[0m     \u001b[38;5;28mself\u001b[39m\u001b[38;5;241m.\u001b[39mon_trial_end(trial)\n\u001b[1;32m    232\u001b[0m \u001b[38;5;28mself\u001b[39m\u001b[38;5;241m.\u001b[39mon_search_end()\n",
      "File \u001b[0;32m~/anaconda3/lib/python3.11/site-packages/keras_tuner/src/engine/base_tuner.py:335\u001b[0m, in \u001b[0;36mBaseTuner.on_trial_end\u001b[0;34m(self, trial)\u001b[0m\n\u001b[1;32m    329\u001b[0m \u001b[38;5;28;01mdef\u001b[39;00m \u001b[38;5;21mon_trial_end\u001b[39m(\u001b[38;5;28mself\u001b[39m, trial):\n\u001b[1;32m    330\u001b[0m \u001b[38;5;250m    \u001b[39m\u001b[38;5;124;03m\"\"\"Called at the end of a trial.\u001b[39;00m\n\u001b[1;32m    331\u001b[0m \n\u001b[1;32m    332\u001b[0m \u001b[38;5;124;03m    Args:\u001b[39;00m\n\u001b[1;32m    333\u001b[0m \u001b[38;5;124;03m        trial: A `Trial` instance.\u001b[39;00m\n\u001b[1;32m    334\u001b[0m \u001b[38;5;124;03m    \"\"\"\u001b[39;00m\n\u001b[0;32m--> 335\u001b[0m     \u001b[38;5;28mself\u001b[39m\u001b[38;5;241m.\u001b[39moracle\u001b[38;5;241m.\u001b[39mend_trial(trial)\n\u001b[1;32m    336\u001b[0m     \u001b[38;5;66;03m# Display needs the updated trial scored by the Oracle.\u001b[39;00m\n\u001b[1;32m    337\u001b[0m     \u001b[38;5;28mself\u001b[39m\u001b[38;5;241m.\u001b[39m_display\u001b[38;5;241m.\u001b[39mon_trial_end(\u001b[38;5;28mself\u001b[39m\u001b[38;5;241m.\u001b[39moracle\u001b[38;5;241m.\u001b[39mget_trial(trial\u001b[38;5;241m.\u001b[39mtrial_id))\n",
      "File \u001b[0;32m~/anaconda3/lib/python3.11/site-packages/keras_tuner/src/engine/oracle.py:107\u001b[0m, in \u001b[0;36msynchronized.<locals>.wrapped_func\u001b[0;34m(*args, **kwargs)\u001b[0m\n\u001b[1;32m    105\u001b[0m     LOCKS[oracle]\u001b[38;5;241m.\u001b[39macquire()\n\u001b[1;32m    106\u001b[0m     THREADS[oracle] \u001b[38;5;241m=\u001b[39m thread_name\n\u001b[0;32m--> 107\u001b[0m ret_val \u001b[38;5;241m=\u001b[39m func(\u001b[38;5;241m*\u001b[39margs, \u001b[38;5;241m*\u001b[39m\u001b[38;5;241m*\u001b[39mkwargs)\n\u001b[1;32m    108\u001b[0m \u001b[38;5;28;01mif\u001b[39;00m need_acquire:\n\u001b[1;32m    109\u001b[0m     THREADS[oracle] \u001b[38;5;241m=\u001b[39m \u001b[38;5;28;01mNone\u001b[39;00m\n",
      "File \u001b[0;32m~/anaconda3/lib/python3.11/site-packages/keras_tuner/src/engine/oracle.py:429\u001b[0m, in \u001b[0;36mOracle.end_trial\u001b[0;34m(self, trial)\u001b[0m\n\u001b[1;32m    427\u001b[0m \u001b[38;5;28;01mif\u001b[39;00m \u001b[38;5;129;01mnot\u001b[39;00m \u001b[38;5;28mself\u001b[39m\u001b[38;5;241m.\u001b[39m_retry(trial):\n\u001b[1;32m    428\u001b[0m     \u001b[38;5;28mself\u001b[39m\u001b[38;5;241m.\u001b[39mend_order\u001b[38;5;241m.\u001b[39mappend(trial\u001b[38;5;241m.\u001b[39mtrial_id)\n\u001b[0;32m--> 429\u001b[0m     \u001b[38;5;28mself\u001b[39m\u001b[38;5;241m.\u001b[39m_check_consecutive_failures()\n\u001b[1;32m    431\u001b[0m \u001b[38;5;28mself\u001b[39m\u001b[38;5;241m.\u001b[39m_save_trial(trial)\n\u001b[1;32m    432\u001b[0m \u001b[38;5;28mself\u001b[39m\u001b[38;5;241m.\u001b[39msave()\n",
      "File \u001b[0;32m~/anaconda3/lib/python3.11/site-packages/keras_tuner/src/engine/oracle.py:386\u001b[0m, in \u001b[0;36mOracle._check_consecutive_failures\u001b[0;34m(self)\u001b[0m\n\u001b[1;32m    384\u001b[0m     consecutive_failures \u001b[38;5;241m=\u001b[39m \u001b[38;5;241m0\u001b[39m\n\u001b[1;32m    385\u001b[0m \u001b[38;5;28;01mif\u001b[39;00m consecutive_failures \u001b[38;5;241m==\u001b[39m \u001b[38;5;28mself\u001b[39m\u001b[38;5;241m.\u001b[39mmax_consecutive_failed_trials:\n\u001b[0;32m--> 386\u001b[0m     \u001b[38;5;28;01mraise\u001b[39;00m \u001b[38;5;167;01mRuntimeError\u001b[39;00m(\n\u001b[1;32m    387\u001b[0m         \u001b[38;5;124m\"\u001b[39m\u001b[38;5;124mNumber of consecutive failures exceeded the limit \u001b[39m\u001b[38;5;124m\"\u001b[39m\n\u001b[1;32m    388\u001b[0m         \u001b[38;5;124mf\u001b[39m\u001b[38;5;124m\"\u001b[39m\u001b[38;5;124mof \u001b[39m\u001b[38;5;132;01m{\u001b[39;00m\u001b[38;5;28mself\u001b[39m\u001b[38;5;241m.\u001b[39mmax_consecutive_failed_trials\u001b[38;5;132;01m}\u001b[39;00m\u001b[38;5;124m.\u001b[39m\u001b[38;5;130;01m\\n\u001b[39;00m\u001b[38;5;124m\"\u001b[39m\n\u001b[1;32m    389\u001b[0m         \u001b[38;5;241m+\u001b[39m (trial\u001b[38;5;241m.\u001b[39mmessage \u001b[38;5;129;01mor\u001b[39;00m \u001b[38;5;124m\"\u001b[39m\u001b[38;5;124m\"\u001b[39m)\n\u001b[1;32m    390\u001b[0m     )\n",
      "\u001b[0;31mRuntimeError\u001b[0m: Number of consecutive failures exceeded the limit of 3.\nTraceback (most recent call last):\n  File \"/Users/khatriaryan/anaconda3/lib/python3.11/site-packages/keras_tuner/src/engine/base_tuner.py\", line 270, in _try_run_and_update_trial\n    self._run_and_update_trial(trial, *fit_args, **fit_kwargs)\n  File \"/Users/khatriaryan/anaconda3/lib/python3.11/site-packages/keras_tuner/src/engine/base_tuner.py\", line 235, in _run_and_update_trial\n    results = self.run_trial(trial, *fit_args, **fit_kwargs)\n              ^^^^^^^^^^^^^^^^^^^^^^^^^^^^^^^^^^^^^^^^^^^^^^\n  File \"/Users/khatriaryan/anaconda3/lib/python3.11/site-packages/keras_tuner/src/engine/tuner.py\", line 314, in run_trial\n    obj_value = self._build_and_fit_model(trial, *args, **copied_kwargs)\n                ^^^^^^^^^^^^^^^^^^^^^^^^^^^^^^^^^^^^^^^^^^^^^^^^^^^^^^^^\n  File \"/Users/khatriaryan/anaconda3/lib/python3.11/site-packages/keras_tuner/src/engine/tuner.py\", line 233, in _build_and_fit_model\n    results = self.hypermodel.fit(hp, model, *args, **kwargs)\n              ^^^^^^^^^^^^^^^^^^^^^^^^^^^^^^^^^^^^^^^^^^^^^^^\n  File \"/Users/khatriaryan/anaconda3/lib/python3.11/site-packages/keras_tuner/src/engine/hypermodel.py\", line 144, in fit\n    return model.fit(*args, **kwargs)\n           ^^^^^^^^^^^^^^^^^^^^^^^^^^\n  File \"/Users/khatriaryan/anaconda3/lib/python3.11/site-packages/keras/src/utils/traceback_utils.py\", line 70, in error_handler\n    raise e.with_traceback(filtered_tb) from None\n  File \"/var/folders/9c/2115fdss5hn7vy9wx2ldrjq40000gn/T/__autograph_generated_file2u8audgp.py\", line 18, in tf__train_function\n    raise\nValueError: in user code:\n\n    File \"/Users/khatriaryan/anaconda3/lib/python3.11/site-packages/keras/src/engine/training.py\", line 1377, in train_function  *\n        return step_function(self, iterator)\n    File \"/Users/khatriaryan/anaconda3/lib/python3.11/site-packages/keras/src/engine/training.py\", line 1360, in step_function  **\n        outputs = model.distribute_strategy.run(run_step, args=(data,))\n    File \"/Users/khatriaryan/anaconda3/lib/python3.11/site-packages/keras/src/engine/training.py\", line 1349, in run_step  **\n        outputs = model.train_step(data)\n    File \"/Users/khatriaryan/anaconda3/lib/python3.11/site-packages/keras/src/engine/training.py\", line 1127, in train_step\n        loss = self.compute_loss(x, y, y_pred, sample_weight)\n    File \"/Users/khatriaryan/anaconda3/lib/python3.11/site-packages/keras/src/engine/training.py\", line 1185, in compute_loss\n        return self.compiled_loss(\n    File \"/Users/khatriaryan/anaconda3/lib/python3.11/site-packages/keras/src/engine/compile_utils.py\", line 252, in __call__\n        self.build(y_pred)\n    File \"/Users/khatriaryan/anaconda3/lib/python3.11/site-packages/keras/src/engine/compile_utils.py\", line 194, in build\n        self._losses = tf.nest.map_structure(\n    File \"/Users/khatriaryan/anaconda3/lib/python3.11/site-packages/keras/src/engine/compile_utils.py\", line 365, in _get_loss_object\n        loss = losses_mod.get(loss)\n    File \"/Users/khatriaryan/anaconda3/lib/python3.11/site-packages/keras/src/losses.py\", line 2965, in get\n        return deserialize(identifier, use_legacy_format=use_legacy_format)\n    File \"/Users/khatriaryan/anaconda3/lib/python3.11/site-packages/keras/src/losses.py\", line 2912, in deserialize\n        return legacy_serialization.deserialize_keras_object(\n    File \"/Users/khatriaryan/anaconda3/lib/python3.11/site-packages/keras/src/saving/legacy/serialization.py\", line 537, in deserialize_keras_object\n        raise ValueError(\n\n    ValueError: Unknown loss function: 'mean_absoulte_error'. Please ensure you are using a `keras.utils.custom_object_scope` and that this object is included in the scope. See https://www.tensorflow.org/guide/keras/save_and_serialize#registering_the_custom_object for details.\n\n"
     ]
    }
   ],
   "source": [
    "tuner.search(X_train, Y_train,\n",
    "             epochs=5,\n",
    "             validation_data=(X_test, Y_test))"
   ]
  },
  {
   "cell_type": "code",
   "execution_count": 37,
   "id": "1ca749d7",
   "metadata": {},
   "outputs": [
    {
     "name": "stdout",
     "output_type": "stream",
     "text": [
      "Results summary\n",
      "Results in project/Air Quality Index\n",
      "Showing 10 best trials\n",
      "Objective(name=\"val_mean_absolute_error\", direction=\"min\")\n",
      "\n",
      "Trial 0 summary\n",
      "Hyperparameters:\n",
      "num_layers: 3\n",
      "units_0: 192\n",
      "learning_rate: 0.001\n",
      "Traceback (most recent call last):\n",
      "  File \"/Users/khatriaryan/anaconda3/lib/python3.11/site-packages/keras_tuner/src/engine/base_tuner.py\", line 270, in _try_run_and_update_trial\n",
      "    self._run_and_update_trial(trial, *fit_args, **fit_kwargs)\n",
      "  File \"/Users/khatriaryan/anaconda3/lib/python3.11/site-packages/keras_tuner/src/engine/base_tuner.py\", line 235, in _run_and_update_trial\n",
      "    results = self.run_trial(trial, *fit_args, **fit_kwargs)\n",
      "              ^^^^^^^^^^^^^^^^^^^^^^^^^^^^^^^^^^^^^^^^^^^^^^\n",
      "  File \"/Users/khatriaryan/anaconda3/lib/python3.11/site-packages/keras_tuner/src/engine/tuner.py\", line 314, in run_trial\n",
      "    obj_value = self._build_and_fit_model(trial, *args, **copied_kwargs)\n",
      "                ^^^^^^^^^^^^^^^^^^^^^^^^^^^^^^^^^^^^^^^^^^^^^^^^^^^^^^^^\n",
      "  File \"/Users/khatriaryan/anaconda3/lib/python3.11/site-packages/keras_tuner/src/engine/tuner.py\", line 233, in _build_and_fit_model\n",
      "    results = self.hypermodel.fit(hp, model, *args, **kwargs)\n",
      "              ^^^^^^^^^^^^^^^^^^^^^^^^^^^^^^^^^^^^^^^^^^^^^^^\n",
      "  File \"/Users/khatriaryan/anaconda3/lib/python3.11/site-packages/keras_tuner/src/engine/hypermodel.py\", line 144, in fit\n",
      "    return model.fit(*args, **kwargs)\n",
      "           ^^^^^^^^^^^^^^^^^^^^^^^^^^\n",
      "  File \"/Users/khatriaryan/anaconda3/lib/python3.11/site-packages/keras/src/utils/traceback_utils.py\", line 70, in error_handler\n",
      "    raise e.with_traceback(filtered_tb) from None\n",
      "  File \"/var/folders/9c/2115fdss5hn7vy9wx2ldrjq40000gn/T/__autograph_generated_file2u8audgp.py\", line 18, in tf__train_function\n",
      "    raise\n",
      "ValueError: in user code:\n",
      "\n",
      "    File \"/Users/khatriaryan/anaconda3/lib/python3.11/site-packages/keras/src/engine/training.py\", line 1377, in train_function  *\n",
      "        return step_function(self, iterator)\n",
      "    File \"/Users/khatriaryan/anaconda3/lib/python3.11/site-packages/keras/src/engine/training.py\", line 1360, in step_function  **\n",
      "        outputs = model.distribute_strategy.run(run_step, args=(data,))\n",
      "    File \"/Users/khatriaryan/anaconda3/lib/python3.11/site-packages/keras/src/engine/training.py\", line 1349, in run_step  **\n",
      "        outputs = model.train_step(data)\n",
      "    File \"/Users/khatriaryan/anaconda3/lib/python3.11/site-packages/keras/src/engine/training.py\", line 1127, in train_step\n",
      "        loss = self.compute_loss(x, y, y_pred, sample_weight)\n",
      "    File \"/Users/khatriaryan/anaconda3/lib/python3.11/site-packages/keras/src/engine/training.py\", line 1185, in compute_loss\n",
      "        return self.compiled_loss(\n",
      "    File \"/Users/khatriaryan/anaconda3/lib/python3.11/site-packages/keras/src/engine/compile_utils.py\", line 252, in __call__\n",
      "        self.build(y_pred)\n",
      "    File \"/Users/khatriaryan/anaconda3/lib/python3.11/site-packages/keras/src/engine/compile_utils.py\", line 194, in build\n",
      "        self._losses = tf.nest.map_structure(\n",
      "    File \"/Users/khatriaryan/anaconda3/lib/python3.11/site-packages/keras/src/engine/compile_utils.py\", line 365, in _get_loss_object\n",
      "        loss = losses_mod.get(loss)\n",
      "    File \"/Users/khatriaryan/anaconda3/lib/python3.11/site-packages/keras/src/losses.py\", line 2965, in get\n",
      "        return deserialize(identifier, use_legacy_format=use_legacy_format)\n",
      "    File \"/Users/khatriaryan/anaconda3/lib/python3.11/site-packages/keras/src/losses.py\", line 2912, in deserialize\n",
      "        return legacy_serialization.deserialize_keras_object(\n",
      "    File \"/Users/khatriaryan/anaconda3/lib/python3.11/site-packages/keras/src/saving/legacy/serialization.py\", line 537, in deserialize_keras_object\n",
      "        raise ValueError(\n",
      "\n",
      "    ValueError: Unknown loss function: 'mean_absoulte_error'. Please ensure you are using a `keras.utils.custom_object_scope` and that this object is included in the scope. See https://www.tensorflow.org/guide/keras/save_and_serialize#registering_the_custom_object for details.\n",
      "\n",
      "\n",
      "\n",
      "Trial 1 summary\n",
      "Hyperparameters:\n",
      "num_layers: 14\n",
      "units_0: 320\n",
      "learning_rate: 0.0001\n",
      "Traceback (most recent call last):\n",
      "  File \"/Users/khatriaryan/anaconda3/lib/python3.11/site-packages/keras_tuner/src/engine/base_tuner.py\", line 270, in _try_run_and_update_trial\n",
      "    self._run_and_update_trial(trial, *fit_args, **fit_kwargs)\n",
      "  File \"/Users/khatriaryan/anaconda3/lib/python3.11/site-packages/keras_tuner/src/engine/base_tuner.py\", line 235, in _run_and_update_trial\n",
      "    results = self.run_trial(trial, *fit_args, **fit_kwargs)\n",
      "              ^^^^^^^^^^^^^^^^^^^^^^^^^^^^^^^^^^^^^^^^^^^^^^\n",
      "  File \"/Users/khatriaryan/anaconda3/lib/python3.11/site-packages/keras_tuner/src/engine/tuner.py\", line 314, in run_trial\n",
      "    obj_value = self._build_and_fit_model(trial, *args, **copied_kwargs)\n",
      "                ^^^^^^^^^^^^^^^^^^^^^^^^^^^^^^^^^^^^^^^^^^^^^^^^^^^^^^^^\n",
      "  File \"/Users/khatriaryan/anaconda3/lib/python3.11/site-packages/keras_tuner/src/engine/tuner.py\", line 233, in _build_and_fit_model\n",
      "    results = self.hypermodel.fit(hp, model, *args, **kwargs)\n",
      "              ^^^^^^^^^^^^^^^^^^^^^^^^^^^^^^^^^^^^^^^^^^^^^^^\n",
      "  File \"/Users/khatriaryan/anaconda3/lib/python3.11/site-packages/keras_tuner/src/engine/hypermodel.py\", line 144, in fit\n",
      "    return model.fit(*args, **kwargs)\n",
      "           ^^^^^^^^^^^^^^^^^^^^^^^^^^\n",
      "  File \"/Users/khatriaryan/anaconda3/lib/python3.11/site-packages/keras/src/utils/traceback_utils.py\", line 70, in error_handler\n",
      "    raise e.with_traceback(filtered_tb) from None\n",
      "  File \"/var/folders/9c/2115fdss5hn7vy9wx2ldrjq40000gn/T/__autograph_generated_file2u8audgp.py\", line 18, in tf__train_function\n",
      "    raise\n",
      "ValueError: in user code:\n",
      "\n",
      "    File \"/Users/khatriaryan/anaconda3/lib/python3.11/site-packages/keras/src/engine/training.py\", line 1377, in train_function  *\n",
      "        return step_function(self, iterator)\n",
      "    File \"/Users/khatriaryan/anaconda3/lib/python3.11/site-packages/keras/src/engine/training.py\", line 1360, in step_function  **\n",
      "        outputs = model.distribute_strategy.run(run_step, args=(data,))\n",
      "    File \"/Users/khatriaryan/anaconda3/lib/python3.11/site-packages/keras/src/engine/training.py\", line 1349, in run_step  **\n",
      "        outputs = model.train_step(data)\n",
      "    File \"/Users/khatriaryan/anaconda3/lib/python3.11/site-packages/keras/src/engine/training.py\", line 1127, in train_step\n",
      "        loss = self.compute_loss(x, y, y_pred, sample_weight)\n",
      "    File \"/Users/khatriaryan/anaconda3/lib/python3.11/site-packages/keras/src/engine/training.py\", line 1185, in compute_loss\n",
      "        return self.compiled_loss(\n",
      "    File \"/Users/khatriaryan/anaconda3/lib/python3.11/site-packages/keras/src/engine/compile_utils.py\", line 252, in __call__\n",
      "        self.build(y_pred)\n",
      "    File \"/Users/khatriaryan/anaconda3/lib/python3.11/site-packages/keras/src/engine/compile_utils.py\", line 194, in build\n",
      "        self._losses = tf.nest.map_structure(\n",
      "    File \"/Users/khatriaryan/anaconda3/lib/python3.11/site-packages/keras/src/engine/compile_utils.py\", line 365, in _get_loss_object\n",
      "        loss = losses_mod.get(loss)\n",
      "    File \"/Users/khatriaryan/anaconda3/lib/python3.11/site-packages/keras/src/losses.py\", line 2965, in get\n",
      "        return deserialize(identifier, use_legacy_format=use_legacy_format)\n",
      "    File \"/Users/khatriaryan/anaconda3/lib/python3.11/site-packages/keras/src/losses.py\", line 2912, in deserialize\n",
      "        return legacy_serialization.deserialize_keras_object(\n",
      "    File \"/Users/khatriaryan/anaconda3/lib/python3.11/site-packages/keras/src/saving/legacy/serialization.py\", line 537, in deserialize_keras_object\n",
      "        raise ValueError(\n",
      "\n",
      "    ValueError: Unknown loss function: 'mean_absoulte_error'. Please ensure you are using a `keras.utils.custom_object_scope` and that this object is included in the scope. See https://www.tensorflow.org/guide/keras/save_and_serialize#registering_the_custom_object for details.\n",
      "\n",
      "\n",
      "\n",
      "Trial 2 summary\n",
      "Hyperparameters:\n",
      "num_layers: 14\n",
      "units_0: 32\n",
      "learning_rate: 0.001\n",
      "Traceback (most recent call last):\n",
      "  File \"/Users/khatriaryan/anaconda3/lib/python3.11/site-packages/keras_tuner/src/engine/base_tuner.py\", line 270, in _try_run_and_update_trial\n",
      "    self._run_and_update_trial(trial, *fit_args, **fit_kwargs)\n",
      "  File \"/Users/khatriaryan/anaconda3/lib/python3.11/site-packages/keras_tuner/src/engine/base_tuner.py\", line 235, in _run_and_update_trial\n",
      "    results = self.run_trial(trial, *fit_args, **fit_kwargs)\n",
      "              ^^^^^^^^^^^^^^^^^^^^^^^^^^^^^^^^^^^^^^^^^^^^^^\n",
      "  File \"/Users/khatriaryan/anaconda3/lib/python3.11/site-packages/keras_tuner/src/engine/tuner.py\", line 314, in run_trial\n",
      "    obj_value = self._build_and_fit_model(trial, *args, **copied_kwargs)\n",
      "                ^^^^^^^^^^^^^^^^^^^^^^^^^^^^^^^^^^^^^^^^^^^^^^^^^^^^^^^^\n",
      "  File \"/Users/khatriaryan/anaconda3/lib/python3.11/site-packages/keras_tuner/src/engine/tuner.py\", line 233, in _build_and_fit_model\n",
      "    results = self.hypermodel.fit(hp, model, *args, **kwargs)\n",
      "              ^^^^^^^^^^^^^^^^^^^^^^^^^^^^^^^^^^^^^^^^^^^^^^^\n",
      "  File \"/Users/khatriaryan/anaconda3/lib/python3.11/site-packages/keras_tuner/src/engine/hypermodel.py\", line 144, in fit\n",
      "    return model.fit(*args, **kwargs)\n",
      "           ^^^^^^^^^^^^^^^^^^^^^^^^^^\n",
      "  File \"/Users/khatriaryan/anaconda3/lib/python3.11/site-packages/keras/src/utils/traceback_utils.py\", line 70, in error_handler\n",
      "    raise e.with_traceback(filtered_tb) from None\n",
      "  File \"/var/folders/9c/2115fdss5hn7vy9wx2ldrjq40000gn/T/__autograph_generated_file2u8audgp.py\", line 18, in tf__train_function\n",
      "    raise\n",
      "ValueError: in user code:\n",
      "\n",
      "    File \"/Users/khatriaryan/anaconda3/lib/python3.11/site-packages/keras/src/engine/training.py\", line 1377, in train_function  *\n",
      "        return step_function(self, iterator)\n",
      "    File \"/Users/khatriaryan/anaconda3/lib/python3.11/site-packages/keras/src/engine/training.py\", line 1360, in step_function  **\n",
      "        outputs = model.distribute_strategy.run(run_step, args=(data,))\n",
      "    File \"/Users/khatriaryan/anaconda3/lib/python3.11/site-packages/keras/src/engine/training.py\", line 1349, in run_step  **\n",
      "        outputs = model.train_step(data)\n",
      "    File \"/Users/khatriaryan/anaconda3/lib/python3.11/site-packages/keras/src/engine/training.py\", line 1127, in train_step\n",
      "        loss = self.compute_loss(x, y, y_pred, sample_weight)\n",
      "    File \"/Users/khatriaryan/anaconda3/lib/python3.11/site-packages/keras/src/engine/training.py\", line 1185, in compute_loss\n",
      "        return self.compiled_loss(\n",
      "    File \"/Users/khatriaryan/anaconda3/lib/python3.11/site-packages/keras/src/engine/compile_utils.py\", line 252, in __call__\n",
      "        self.build(y_pred)\n",
      "    File \"/Users/khatriaryan/anaconda3/lib/python3.11/site-packages/keras/src/engine/compile_utils.py\", line 194, in build\n",
      "        self._losses = tf.nest.map_structure(\n",
      "    File \"/Users/khatriaryan/anaconda3/lib/python3.11/site-packages/keras/src/engine/compile_utils.py\", line 365, in _get_loss_object\n",
      "        loss = losses_mod.get(loss)\n",
      "    File \"/Users/khatriaryan/anaconda3/lib/python3.11/site-packages/keras/src/losses.py\", line 2965, in get\n",
      "        return deserialize(identifier, use_legacy_format=use_legacy_format)\n",
      "    File \"/Users/khatriaryan/anaconda3/lib/python3.11/site-packages/keras/src/losses.py\", line 2912, in deserialize\n",
      "        return legacy_serialization.deserialize_keras_object(\n",
      "    File \"/Users/khatriaryan/anaconda3/lib/python3.11/site-packages/keras/src/saving/legacy/serialization.py\", line 537, in deserialize_keras_object\n",
      "        raise ValueError(\n",
      "\n",
      "    ValueError: Unknown loss function: 'mean_absoulte_error'. Please ensure you are using a `keras.utils.custom_object_scope` and that this object is included in the scope. See https://www.tensorflow.org/guide/keras/save_and_serialize#registering_the_custom_object for details.\n",
      "\n",
      "\n"
     ]
    }
   ],
   "source": [
    "tuner.results_summary()"
   ]
  },
  {
   "cell_type": "code",
   "execution_count": null,
   "id": "5c0ebe62",
   "metadata": {},
   "outputs": [],
   "source": []
  }
 ],
 "metadata": {
  "kernelspec": {
   "display_name": "Python 3 (ipykernel)",
   "language": "python",
   "name": "python3"
  },
  "language_info": {
   "codemirror_mode": {
    "name": "ipython",
    "version": 3
   },
   "file_extension": ".py",
   "mimetype": "text/x-python",
   "name": "python",
   "nbconvert_exporter": "python",
   "pygments_lexer": "ipython3",
   "version": "3.11.3"
  }
 },
 "nbformat": 4,
 "nbformat_minor": 5
}
